<?xml version="1.0" ?>
<!-- =================================================================================== -->
<!-- |    This document was autogenerated by xacro from mobile_manipulator.urdf.xacro  | -->
<!-- |    EDITING THIS FILE BY HAND IS NOT RECOMMENDED                                 | -->
<!-- =================================================================================== -->
<robot name="mobile_ur10" xmlns:xacro="http://ros.org/wiki/xacro">

    <!-- mobile base description -->
    <xacro:include filename="$(find mobile_manipulator)/models/mobile_base/mobile_base.urdf.xacro"/>
    
    <joint name="arm_to_mobile_base" type="fixed">
    <!--origin xyz="0 0 ${.352 / 2}" rpy="0 0 0" /-->
        <origin xyz="0 0 0.638" rpy="0 0 -1.5408" />
        <parent link="chassis" />
        <child link="base_link" />    
    </joint>

<!--    < World link --> -->

<!--    <link name="world" />-->
<!--    <joint name="platform_to_world" type="fixed">-->
<!--        <origin rpy="0 0 0" xyz="0 0 0.920" />-->
<!--        <parent link="world" />-->
<!--        <child link="base_link" />-->
<!--        <limit effort="1000.0" lower="-100" upper="100" velocity="2" />-->
<!--    </joint>-->

    <!-- Measured from model -->

    <link name="base_link">
        <visual>
            <geometry>
                <mesh filename="package://ur_description/meshes/ur10/visual/base.dae" />
            </geometry>
            <material name="LightGrey">
                <color rgba="0.7 0.7 0.7 1.0" />
            </material>
        </visual>
        <collision>
            <geometry>
                <mesh filename="package://ur_description/meshes/ur10/collision/base.stl" />
            </geometry>
        </collision>
	<inertial>
            <mass value="4.0" />
            <origin rpy="0 0 0" xyz="0.0 0.0 .125" />
            <inertia ixx="0.0061063308908" ixy="0.0" ixz="0.0" iyy="0.0061063308908" iyz="0.0" izz="0.01125" />
        </inertial>
    </link>

    <joint name="shoulder_pan_joint" type="revolute">
        <parent link="base_link" />
        <child link="shoulder_link" />
        <origin rpy="0.0 0.0 0.0" xyz="0.0 0.0 0.1273" />
        <axis xyz="0 0 1" />
        <limit effort="330.0" lower="-3.14159265359" upper="3.14159265359" velocity="2.16" />
        <dynamics damping="0.0" friction="0.0" />
    </joint>

    <link name="shoulder_link">
        <visual>
            <geometry>
                <mesh filename="package://ur_description/meshes/ur10/visual/shoulder.dae" />
            </geometry>
            <material name="LightGrey">
                <color rgba="0.7 0.7 0.7 1.0" />
            </material>
        </visual>
        <collision>
            <geometry>
                <mesh filename="package://ur_description/meshes/ur10/collision/shoulder.stl" />
            </geometry>
        </collision>      
	<inertial>
            <mass value="7.778" />
            <origin rpy="0 0 0" xyz="0.0 0.0 0.0" />
            <inertia ixx="0.0314743125769" ixy="0.0" ixz="0.0" iyy="0.0314743125769" iyz="0.0" izz="0.021875625" />
        </inertial>
    </link>

    <joint name="shoulder_lift_joint" type="revolute">
        <parent link="shoulder_link" />
        <child link="upper_arm_link" />
        <origin rpy="0.0 1.57079632679 0.0" xyz="0.0 0.220941 0.0" />
        <axis xyz="0 1 0" />
        <limit effort="330.0" lower="-3.14159265359" upper="3.14159265359" velocity="2.16" />
        <dynamics damping="0.0" friction="0.0" />
    </joint>

    <link name="upper_arm_link">
        <visual>
            <geometry>
                <mesh filename="package://ur_description/meshes/ur10/visual/upperarm.dae" />
            </geometry>
            <material name="LightGrey">
                <color rgba="0.7 0.7 0.7 1.0" />
            </material>
        </visual>
        <collision>
            <geometry>
                <mesh filename="package://ur_description/meshes/ur10/collision/upperarm.stl" />
            </geometry>
        </collision>        
	<inertial>
            <mass value="12.93" />
            <origin rpy="0 0 0" xyz="0.0 0.0 0.306" />
            <inertia ixx="0.421753803798" ixy="0.0" ixz="0.0" iyy="0.421753803798" iyz="0.0" izz="0.036365625" />
        </inertial>
    </link>

    <joint name="elbow_joint" type="revolute">
        <parent link="upper_arm_link" />
        <child link="forearm_link" />
        <origin rpy="0.0 0.0 0.0" xyz="0.0 -0.1719 0.612" />
        <axis xyz="0 1 0" />
        <limit effort="150.0" lower="-3.14159265359" upper="3.14159265359" velocity="3.15" />
        <dynamics damping="0.0" friction="0.0" />
    </joint>

    <link name="forearm_link">
        <visual>
            <geometry>
                <mesh filename="package://ur_description/meshes/ur10/visual/forearm.dae" />
            </geometry>
            <material name="LightGrey">
                <color rgba="0.7 0.7 0.7 1.0" />
            </material>
        </visual>
        <collision>
            <geometry>
                <mesh filename="package://ur_description/meshes/ur10/collision/forearm.stl" />
            </geometry>
        </collision>        
	<inertial>
            <mass value="3.87" />
            <origin rpy="0 0 0" xyz="0.0 0.0 0.28615" />
            <inertia ixx="0.111069694097" ixy="0.0" ixz="0.0" iyy="0.111069694097" iyz="0.0" izz="0.010884375" />
        </inertial>
    </link>

    <joint name="wrist_1_joint" type="revolute">
        <parent link="forearm_link" />
        <child link="wrist_1_link" />
        <origin rpy="0.0 1.57079632679 0.0" xyz="0.0 0.0 0.5723" />
        <axis xyz="0 1 0" />
        <limit effort="54.0" lower="-3.14159265359" upper="3.14159265359" velocity="3.2" />
        <dynamics damping="0.0" friction="0.0" />
    </joint>

    <link name="wrist_1_link">
        <visual>
            <geometry>
                <mesh filename="package://ur_description/meshes/ur10/visual/wrist1.dae" />
            </geometry>
            <material name="LightGrey">
                <color rgba="0.7 0.7 0.7 1.0" />
            </material>
        </visual>
        <collision>
            <geometry>
                <mesh filename="package://ur_description/meshes/ur10/collision/wrist1.stl" />
            </geometry>
        </collision>        
	<inertial>
            <mass value="1.96" />
            <origin rpy="0 0 0" xyz="0.0 0.0 0.0" />
            <inertia ixx="0.0051082479567" ixy="0.0" ixz="0.0" iyy="0.0051082479567" iyz="0.0" izz="0.0055125" />
        </inertial>
    </link>

    <joint name="wrist_2_joint" type="revolute">
        <parent link="wrist_1_link" />
        <child link="wrist_2_link" />
        <origin rpy="0.0 0.0 0.0" xyz="0.0 0.1149 0.0" />
        <axis xyz="0 0 1" />
        <limit effort="54.0" lower="-3.14159265359" upper="3.14159265359" velocity="3.2" />
        <dynamics damping="0.0" friction="0.0" />
    </joint>

    <link name="wrist_2_link">
        <visual>
            <geometry>
                <mesh filename="package://ur_description/meshes/ur10/visual/wrist2.dae" />
            </geometry>
            <material name="LightGrey">
                <color rgba="0.7 0.7 0.7 1.0" />
            </material>
        </visual>
        <collision>
            <geometry>
                <mesh filename="package://ur_description/meshes/ur10/collision/wrist2.stl" />
            </geometry>
        </collision>        
	<inertial>
            <mass value="1.96" />
            <origin rpy="0 0 0" xyz="0.0 0.0 0.0" />
            <inertia ixx="0.0051082479567" ixy="0.0" ixz="0.0" iyy="0.0051082479567" iyz="0.0" izz="0.0055125" />
        </inertial>
    </link>

    <joint name="wrist_3_joint" type="revolute">
        <parent link="wrist_2_link" />
        <child link="wrist_3_link" />
        <origin rpy="0.0 0.0 0.0" xyz="0.0 0.0 0.1157" />
        <axis xyz="0 1 0" />
        <limit effort="54.0" lower="-3.14159265359" upper="3.14159265359" velocity="3.2" />
        <dynamics damping="0.0" friction="0.0" />
    </joint>

    <link name="wrist_3_link">
        <visual>
            <geometry>
                <mesh filename="package://ur_description/meshes/ur10/visual/wrist3.dae" />
            </geometry>
            <material name="LightGrey">
                <color rgba="0.7 0.7 0.7 1.0" />
            </material>
        </visual>
        <collision>
            <geometry>
                <mesh filename="package://ur_description/meshes/ur10/collision/wrist3.stl" />
            </geometry>
        </collision>        
	<inertial>
            <mass value="0.202" />
            <origin rpy="0 0 0" xyz="0.0 0.0 0.0" />
            <inertia ixx="0.000526462289415" ixy="0.0" ixz="0.0" iyy="0.000526462289415" iyz="0.0" izz="0.000568125" />
        </inertial>
    </link>

    <joint name="ee_fixed_joint" type="fixed">
        <parent link="wrist_3_link" />
        <child link="ee_link" />
        <origin rpy="0.0 0.0 1.57079632679" xyz="0.0 0.0922 0.0" />
    </joint>

    <link name="ee_link">
        <collision>
            <geometry>
                <box size="0.01 0.01 0.01" />
            </geometry>
            <origin rpy="0 0 0" xyz="-0.01 0 0" />
        </collision>       
	<inertial>
            <mass value="0.1" />
            <inertia ixx="0.03" iyy="0.03" izz="0.03" ixy="0.0" ixz="0.0" iyz="0.0" />
        </inertial>
    </link>

    <!-- Transmissions -->

    <transmission name="shoulder_pan_trans">
        <type>transmission_interface/SimpleTransmission</type>
        <joint name="shoulder_pan_joint">
            <hardwareInterface>hardware_interface/PositionJointInterface</hardwareInterface>
        </joint>
        <actuator name="shoulder_pan_motor">
            <mechanicalReduction>1</mechanicalReduction>
        </actuator>
    </transmission>

    <transmission name="shoulder_lift_trans">
        <type>transmission_interface/SimpleTransmission</type>
        <joint name="shoulder_lift_joint">
            <hardwareInterface>hardware_interface/PositionJointInterface</hardwareInterface>
        </joint>
        <actuator name="shoulder_lift_motor">
            <mechanicalReduction>1</mechanicalReduction>
        </actuator>
    </transmission>

    <transmission name="elbow_trans">
        <type>transmission_interface/SimpleTransmission</type>
        <joint name="elbow_joint">
            <hardwareInterface>hardware_interface/PositionJointInterface</hardwareInterface>
        </joint>
        <actuator name="elbow_motor">
            <mechanicalReduction>1</mechanicalReduction>
        </actuator>
    </transmission>

    <transmission name="wrist_1_trans">
        <type>transmission_interface/SimpleTransmission</type>
        <joint name="wrist_1_joint">
            <hardwareInterface>hardware_interface/PositionJointInterface</hardwareInterface>
        </joint>
        <actuator name="wrist_1_motor">
            <mechanicalReduction>1</mechanicalReduction>
        </actuator>
    </transmission>

    <transmission name="wrist_2_trans">
        <type>transmission_interface/SimpleTransmission</type>
        <joint name="wrist_2_joint">
            <hardwareInterface>hardware_interface/PositionJointInterface</hardwareInterface>
        </joint>
        <actuator name="wrist_2_motor">
            <mechanicalReduction>1</mechanicalReduction>
        </actuator>
    </transmission>

    <transmission name="wrist_3_trans">
        <type>transmission_interface/SimpleTransmission</type>
        <joint name="wrist_3_joint">
            <hardwareInterface>hardware_interface/PositionJointInterface</hardwareInterface>
        </joint>
        <actuator name="wrist_3_motor">
            <mechanicalReduction>1</mechanicalReduction>
        </actuator>
    </transmission>
    
    <!-- ROS base_link to UR 'Base' Coordinates transform -->

    <link name="base"/>

    <joint name="base_link-base_fixed_joint" type="fixed">
        <origin rpy="0 0 -3.14159265359" xyz="0 0 0"/>
        <parent link="base_link"/>
        <child link="base"/>
    </joint>

    <!-- Frame coincident with all-zeros TCP on UR controller -->

    <link name="tool0"/>

    <joint name="wrist_3_link-tool0_fixed_joint" type="fixed">
        <origin rpy="-1.57079632679 0 0" xyz="0 0.0922 0"/>
        <parent link="wrist_3_link"/>
        <child link="tool0"/>
    </joint>

    <!-- Floating Cone as End Effector -->

    <link name="cone_link">
        <visual>
            <origin rpy="0 0 0" xyz="0 0.093 0.11"/>
            <geometry>
                <mesh filename="package://mobile_manipulator/models/fixed_cone/meshes/Cone100.STL"/>
            </geometry>
        </visual>
        <collision>
            <origin rpy="0 0 0" xyz="0 0.093 0.11"/>
            <geometry>
                <mesh filename="package://mobile_manipulator/models/fixed_cone/meshes/Cone100.STL"/>
            </geometry>
        </collision>  
	<inertial>
            <mass value="1" />
            <inertia ixx="0.01" ixy="0.005" ixz="0.0003" iyy="0.02" iyz="0.00004" izz="0.02"/>
        </inertial>
    </link>

    <joint name="floating_cone" type="fixed">
        <origin rpy="0 0 0" xyz="0 0 0"/> 
        <!--z=0.295 ~== cone face flush with tool-->
        <parent link="tool0"/>
        <child link="cone_link"/>
    </joint>

    <!-- Gazebo Plugin -->

    <gazebo>
        <plugin filename="libgazebo_ros_control.so" name="ros_control"/>
    </gazebo>

    <!-- Include Kinect Sensor -->

    <xacro:include filename="$(find art_gazebo)/description/kinect_sensor.urdf.xacro">
    </xacro:include>


</robot>


