<?xml version="1.0" ?>
<!-- =================================================================================== -->
<!-- |    This document was autogenerated by xacro from mobile_manipulator.urdf.xacro  | -->
<!-- |    EDITING THIS FILE BY HAND IS NOT RECOMMENDED                                 | -->
<!-- =================================================================================== -->
<robot name="mobile_ur10" xmlns:xacro="http://ros.org/wiki/xacro">
  <!-- Chassis link -->
  <link name="chassis">
    <visual name="visual">
      <geometry>
        <box size="0.89 0.58 0.2"/>
      </geometry>
    </visual>
    <collision name="collision">
      <geometry>
        <box size="0.89 0.58 0.2"/>
      </geometry>
    </collision>
    <inertial>
      <mass value="63.65"/>
      <inertia ixx="1.99648833333" ixy="0.0" ixz="0.0" iyy="4.41359708333" iyz="0.0" izz="5.98575208333"/>
    </inertial>
  </link>
  <link name="wheel_1_link">
    <!-- Note: must omit name="foo" because in Gazebo 7 the urdf parser has a bug that would make <gazebo reference="bar"> not work -->
    <visual>
      <geometry>
        <cylinder length="0.02" radius="0.071"/>
      </geometry>
      <material name="red">
        <color rgba="1 0 0 1"/>
      </material>
    </visual>
    <!-- Note: must omit name="foo" because in Gazebo 7 the urdf parser has a bug that would make <gazebo reference="bar"> not work -->
    <collision>
      <geometry>
        <cylinder length="0.02" radius="0.071"/>
      </geometry>
    </collision>
    <inertial>
      <mass value="0.558333333333"/>
      <inertia ixx="0.000722250694444" ixy="0.0" ixz="0.0" iyy="0.000722250694444" iyz="0.0" izz="0.00140727916667"/>
    </inertial>
  </link>
  <joint name="wheel_1_joint" type="fixed">
    <axis xyz="0 0 1"/>
    <parent link="chassis"/>
    <child link="wheel_1_link"/>
    <origin rpy="-1.57079632679 0 0" xyz="0.374 0.28 -0.181"/>
  </joint>
  <link name="wheel_2_link">
    <!-- Note: must omit name="foo" because in Gazebo 7 the urdf parser has a bug that would make <gazebo reference="bar"> not work -->
    <visual>
      <geometry>
        <cylinder length="0.02" radius="0.071"/>
      </geometry>
      <material name="red">
        <color rgba="1 0 0 1"/>
      </material>
    </visual>
    <!-- Note: must omit name="foo" because in Gazebo 7 the urdf parser has a bug that would make <gazebo reference="bar"> not work -->
    <collision>
      <geometry>
        <cylinder length="0.02" radius="0.071"/>
      </geometry>
    </collision>
    <inertial>
      <mass value="0.558333333333"/>
      <inertia ixx="0.000722250694444" ixy="0.0" ixz="0.0" iyy="0.000722250694444" iyz="0.0" izz="0.00140727916667"/>
    </inertial>
  </link>
  <joint name="wheel_2_joint" type="fixed">
    <axis xyz="0 0 1"/>
    <parent link="chassis"/>
    <child link="wheel_2_link"/>
    <origin rpy="-1.57079632679 0 0" xyz="0 0.28 -0.181"/>
  </joint>
  <link name="wheel_3_link">
    <!-- Note: must omit name="foo" because in Gazebo 7 the urdf parser has a bug that would make <gazebo reference="bar"> not work -->
    <visual>
      <geometry>
        <cylinder length="0.02" radius="0.071"/>
      </geometry>
      <material name="red">
        <color rgba="1 0 0 1"/>
      </material>
    </visual>
    <!-- Note: must omit name="foo" because in Gazebo 7 the urdf parser has a bug that would make <gazebo reference="bar"> not work -->
    <collision>
      <geometry>
        <cylinder length="0.02" radius="0.071"/>
      </geometry>
    </collision>
    <inertial>
      <mass value="0.558333333333"/>
      <inertia ixx="0.000722250694444" ixy="0.0" ixz="0.0" iyy="0.000722250694444" iyz="0.0" izz="0.00140727916667"/>
    </inertial>
  </link>
  <joint name="wheel_3_joint" type="fixed">
    <axis xyz="0 0 1"/>
    <parent link="chassis"/>
    <child link="wheel_3_link"/>
    <origin rpy="-1.57079632679 0 0" xyz="-0.374 0.28 -0.181"/>
  </joint>
  <link name="wheel_4_link">
    <!-- Note: must omit name="foo" because in Gazebo 7 the urdf parser has a bug that would make <gazebo reference="bar"> not work -->
    <visual>
      <geometry>
        <cylinder length="0.02" radius="0.071"/>
      </geometry>
      <material name="red">
        <color rgba="1 0 0 1"/>
      </material>
    </visual>
    <!-- Note: must omit name="foo" because in Gazebo 7 the urdf parser has a bug that would make <gazebo reference="bar"> not work -->
    <collision>
      <geometry>
        <cylinder length="0.02" radius="0.071"/>
      </geometry>
    </collision>
    <inertial>
      <mass value="0.558333333333"/>
      <inertia ixx="0.000722250694444" ixy="0.0" ixz="0.0" iyy="0.000722250694444" iyz="0.0" izz="0.00140727916667"/>
    </inertial>
  </link>
  <joint name="wheel_4_joint" type="fixed">
    <axis xyz="0 0 1"/>
    <parent link="chassis"/>
    <child link="wheel_4_link"/>
    <origin rpy="-1.57079632679 0 0" xyz="-0.374 -0.28 -0.181"/>
  </joint>
  <link name="wheel_5_link">
    <!-- Note: must omit name="foo" because in Gazebo 7 the urdf parser has a bug that would make <gazebo reference="bar"> not work -->
    <visual>
      <geometry>
        <cylinder length="0.02" radius="0.071"/>
      </geometry>
      <material name="red">
        <color rgba="1 0 0 1"/>
      </material>
    </visual>
    <!-- Note: must omit name="foo" because in Gazebo 7 the urdf parser has a bug that would make <gazebo reference="bar"> not work -->
    <collision>
      <geometry>
        <cylinder length="0.02" radius="0.071"/>
      </geometry>
    </collision>
    <inertial>
      <mass value="0.558333333333"/>
      <inertia ixx="0.000722250694444" ixy="0.0" ixz="0.0" iyy="0.000722250694444" iyz="0.0" izz="0.00140727916667"/>
    </inertial>
  </link>
  <joint name="wheel_5_joint" type="fixed">
    <axis xyz="0 0 1"/>
    <parent link="chassis"/>
    <child link="wheel_5_link"/>
    <origin rpy="-1.57079632679 0 0" xyz="0 -0.28 -0.181"/>
  </joint>
  <link name="wheel_6_link">
    <!-- Note: must omit name="foo" because in Gazebo 7 the urdf parser has a bug that would make <gazebo reference="bar"> not work -->
    <visual>
      <geometry>
        <cylinder length="0.02" radius="0.071"/>
      </geometry>
      <material name="red">
        <color rgba="1 0 0 1"/>
      </material>
    </visual>
    <!-- Note: must omit name="foo" because in Gazebo 7 the urdf parser has a bug that would make <gazebo reference="bar"> not work -->
    <collision>
      <geometry>
        <cylinder length="0.02" radius="0.071"/>
      </geometry>
    </collision>
    <inertial>
      <mass value="0.558333333333"/>
      <inertia ixx="0.000722250694444" ixy="0.0" ixz="0.0" iyy="0.000722250694444" iyz="0.0" izz="0.00140727916667"/>
    </inertial>
  </link>
  <joint name="wheel_6_joint" type="fixed">
    <axis xyz="0 0 1"/>
    <parent link="chassis"/>
    <child link="wheel_6_link"/>
    <origin rpy="-1.57079632679 0 0" xyz="0.374 -0.28 -0.181"/>
  </joint>
  <link name="world"/>
  <joint name="prismatic_chassis_to_world" type="prismatic">
    <origin rpy="0 0 0" xyz="0 0 0.252"/>
    <parent link="world"/>
    <child link="chassis"/>
    <limit effort="1000.0" lower="-100" upper="100" velocity="2"/>
  </joint>
  <transmission name="prismatic_chassis_to_world_trans">
    <type>transmission_interface/SimpleTransmission</type>
    <joint name="prismatic_chassis_to_world">
      <hardwareInterface>hardware_interface/EffortJointInterface</hardwareInterface>
    </joint>
    <actuator name="prismatic_chassis_to_world_motor">
      <hardwareInterface>hardware_interface/EffortJointInterface</hardwareInterface>
      <mechanicalReduction>1</mechanicalReduction>
    </actuator>
  </transmission>
  <!--
  Author: Kelsey Hawkins
  Contributers: Jimmy Da Silva, Ajit Krisshna N L, Muhammad Asif Rana
-->
  <!-- measured from model -->
  <link name="base_link">
    <visual>
      <geometry>
        <mesh filename="package://ur_description/meshes/ur10/visual/base.dae"/>
      </geometry>
      <material name="LightGrey">
        <color rgba="0.7 0.7 0.7 1.0"/>
      </material>
    </visual>
    <collision>
      <geometry>
        <mesh filename="package://ur_description/meshes/ur10/collision/base.stl"/>
      </geometry>
    </collision>
    <inertial>
      <mass value="4.0"/>
      <origin rpy="0 0 0" xyz="0.0 0.0 0.0"/>
      <inertia ixx="0.0061063308908" ixy="0.0" ixz="0.0" iyy="0.0061063308908" iyz="0.0" izz="0.01125"/>
    </inertial>
  </link>
  <joint name="shoulder_pan_joint" type="revolute">
    <parent link="base_link"/>
    <child link="shoulder_link"/>
    <origin rpy="0.0 0.0 0.0" xyz="0.0 0.0 0.1273"/>
    <axis xyz="0 0 1"/>
    <limit effort="330.0" lower="-3.14159265359" upper="3.14159265359" velocity="2.16"/>
    <dynamics damping="0.0" friction="0.0"/>
  </joint>
  <link name="shoulder_link">
    <visual>
      <geometry>
        <mesh filename="package://ur_description/meshes/ur10/visual/shoulder.dae"/>
      </geometry>
      <material name="LightGrey">
        <color rgba="0.7 0.7 0.7 1.0"/>
      </material>
    </visual>
    <collision>
      <geometry>
        <mesh filename="package://ur_description/meshes/ur10/collision/shoulder.stl"/>
      </geometry>
    </collision>
    <inertial>
      <mass value="7.778"/>
      <origin rpy="0 0 0" xyz="0.0 0.0 0.0"/>
      <inertia ixx="0.0314743125769" ixy="0.0" ixz="0.0" iyy="0.0314743125769" iyz="0.0" izz="0.021875625"/>
    </inertial>
  </link>
  <joint name="shoulder_lift_joint" type="revolute">
    <parent link="shoulder_link"/>
    <child link="upper_arm_link"/>
    <origin rpy="0.0 1.57079632679 0.0" xyz="0.0 0.220941 0.0"/>
    <axis xyz="0 1 0"/>
    <limit effort="330.0" lower="-3.14159265359" upper="3.14159265359" velocity="2.16"/>
    <dynamics damping="0.0" friction="0.0"/>
  </joint>
  <link name="upper_arm_link">
    <visual>
      <geometry>
        <mesh filename="package://ur_description/meshes/ur10/visual/upperarm.dae"/>
      </geometry>
      <material name="LightGrey">
        <color rgba="0.7 0.7 0.7 1.0"/>
      </material>
    </visual>
    <collision>
      <geometry>
        <mesh filename="package://ur_description/meshes/ur10/collision/upperarm.stl"/>
      </geometry>
    </collision>
    <inertial>
      <mass value="12.93"/>
      <origin rpy="0 0 0" xyz="0.0 0.0 0.306"/>
      <inertia ixx="0.421753803798" ixy="0.0" ixz="0.0" iyy="0.421753803798" iyz="0.0" izz="0.036365625"/>
    </inertial>
  </link>
  <joint name="elbow_joint" type="revolute">
    <parent link="upper_arm_link"/>
    <child link="forearm_link"/>
    <origin rpy="0.0 0.0 0.0" xyz="0.0 -0.1719 0.612"/>
    <axis xyz="0 1 0"/>
    <limit effort="150.0" lower="-3.14159265359" upper="3.14159265359" velocity="3.15"/>
    <dynamics damping="0.0" friction="0.0"/>
  </joint>
  <link name="forearm_link">
    <visual>
      <geometry>
        <mesh filename="package://ur_description/meshes/ur10/visual/forearm.dae"/>
      </geometry>
      <material name="LightGrey">
        <color rgba="0.7 0.7 0.7 1.0"/>
      </material>
    </visual>
    <collision>
      <geometry>
        <mesh filename="package://ur_description/meshes/ur10/collision/forearm.stl"/>
      </geometry>
    </collision>
    <inertial>
      <mass value="3.87"/>
      <origin rpy="0 0 0" xyz="0.0 0.0 0.28615"/>
      <inertia ixx="0.111069694097" ixy="0.0" ixz="0.0" iyy="0.111069694097" iyz="0.0" izz="0.010884375"/>
    </inertial>
  </link>
  <joint name="wrist_1_joint" type="revolute">
    <parent link="forearm_link"/>
    <child link="wrist_1_link"/>
    <origin rpy="0.0 1.57079632679 0.0" xyz="0.0 0.0 0.5723"/>
    <axis xyz="0 1 0"/>
    <limit effort="54.0" lower="-3.14159265359" upper="3.14159265359" velocity="3.2"/>
    <dynamics damping="0.0" friction="0.0"/>
  </joint>
  <link name="wrist_1_link">
    <visual>
      <geometry>
        <mesh filename="package://ur_description/meshes/ur10/visual/wrist1.dae"/>
      </geometry>
      <material name="LightGrey">
        <color rgba="0.7 0.7 0.7 1.0"/>
      </material>
    </visual>
    <collision>
      <geometry>
        <mesh filename="package://ur_description/meshes/ur10/collision/wrist1.stl"/>
      </geometry>
    </collision>
    <inertial>
      <mass value="1.96"/>
      <origin rpy="0 0 0" xyz="0.0 0.0 0.0"/>
      <inertia ixx="0.0051082479567" ixy="0.0" ixz="0.0" iyy="0.0051082479567" iyz="0.0" izz="0.0055125"/>
    </inertial>
  </link>
  <joint name="wrist_2_joint" type="revolute">
    <parent link="wrist_1_link"/>
    <child link="wrist_2_link"/>
    <origin rpy="0.0 0.0 0.0" xyz="0.0 0.1149 0.0"/>
    <axis xyz="0 0 1"/>
    <limit effort="54.0" lower="-3.14159265359" upper="3.14159265359" velocity="3.2"/>
    <dynamics damping="0.0" friction="0.0"/>
  </joint>
  <link name="wrist_2_link">
    <visual>
      <geometry>
        <mesh filename="package://ur_description/meshes/ur10/visual/wrist2.dae"/>
      </geometry>
      <material name="LightGrey">
        <color rgba="0.7 0.7 0.7 1.0"/>
      </material>
    </visual>
    <collision>
      <geometry>
        <mesh filename="package://ur_description/meshes/ur10/collision/wrist2.stl"/>
      </geometry>
    </collision>
    <inertial>
      <mass value="1.96"/>
      <origin rpy="0 0 0" xyz="0.0 0.0 0.0"/>
      <inertia ixx="0.0051082479567" ixy="0.0" ixz="0.0" iyy="0.0051082479567" iyz="0.0" izz="0.0055125"/>
    </inertial>
  </link>
  <joint name="wrist_3_joint" type="revolute">
    <parent link="wrist_2_link"/>
    <child link="wrist_3_link"/>
    <origin rpy="0.0 0.0 0.0" xyz="0.0 0.0 0.1157"/>
    <axis xyz="0 1 0"/>
    <limit effort="54.0" lower="-3.14159265359" upper="3.14159265359" velocity="3.2"/>
    <dynamics damping="0.0" friction="0.0"/>
  </joint>
  <link name="wrist_3_link">
    <visual>
      <geometry>
        <mesh filename="package://ur_description/meshes/ur10/visual/wrist3.dae"/>
      </geometry>
      <material name="LightGrey">
        <color rgba="0.7 0.7 0.7 1.0"/>
      </material>
    </visual>
    <collision>
      <geometry>
        <mesh filename="package://ur_description/meshes/ur10/collision/wrist3.stl"/>
      </geometry>
    </collision>
    <inertial>
      <mass value="0.202"/>
      <origin rpy="0 0 0" xyz="0.0 0.0 0.0"/>
      <inertia ixx="0.000526462289415" ixy="0.0" ixz="0.0" iyy="0.000526462289415" iyz="0.0" izz="0.000568125"/>
    </inertial>
  </link>
  <joint name="ee_fixed_joint" type="fixed">
    <parent link="wrist_3_link"/>
    <child link="ee_link"/>
    <origin rpy="0.0 0.0 1.57079632679" xyz="0.0 0.0922 0.0"/>
  </joint>
  <link name="ee_link">
    <collision>
      <geometry>
        <box size="0.01 0.01 0.01"/>
      </geometry>
      <origin rpy="0 0 0" xyz="-0.01 0 0"/>
    </collision>
  </link>
  <transmission name="shoulder_pan_trans">
    <type>transmission_interface/SimpleTransmission</type>
    <joint name="shoulder_pan_joint">
      <hardwareInterface>hardware_interface/PositionJointInterface</hardwareInterface>
    </joint>
    <actuator name="shoulder_pan_motor">
      <mechanicalReduction>1</mechanicalReduction>
    </actuator>
  </transmission>
  <transmission name="shoulder_lift_trans">
    <type>transmission_interface/SimpleTransmission</type>
    <joint name="shoulder_lift_joint">
      <hardwareInterface>hardware_interface/PositionJointInterface</hardwareInterface>
    </joint>
    <actuator name="shoulder_lift_motor">
      <mechanicalReduction>1</mechanicalReduction>
    </actuator>
  </transmission>
  <transmission name="elbow_trans">
    <type>transmission_interface/SimpleTransmission</type>
    <joint name="elbow_joint">
      <hardwareInterface>hardware_interface/PositionJointInterface</hardwareInterface>
    </joint>
    <actuator name="elbow_motor">
      <mechanicalReduction>1</mechanicalReduction>
    </actuator>
  </transmission>
  <transmission name="wrist_1_trans">
    <type>transmission_interface/SimpleTransmission</type>
    <joint name="wrist_1_joint">
      <hardwareInterface>hardware_interface/PositionJointInterface</hardwareInterface>
    </joint>
    <actuator name="wrist_1_motor">
      <mechanicalReduction>1</mechanicalReduction>
    </actuator>
  </transmission>
  <transmission name="wrist_2_trans">
    <type>transmission_interface/SimpleTransmission</type>
    <joint name="wrist_2_joint">
      <hardwareInterface>hardware_interface/PositionJointInterface</hardwareInterface>
    </joint>
    <actuator name="wrist_2_motor">
      <mechanicalReduction>1</mechanicalReduction>
    </actuator>
  </transmission>
  <transmission name="wrist_3_trans">
    <type>transmission_interface/SimpleTransmission</type>
    <joint name="wrist_3_joint">
      <hardwareInterface>hardware_interface/PositionJointInterface</hardwareInterface>
    </joint>
    <actuator name="wrist_3_motor">
      <mechanicalReduction>1</mechanicalReduction>
    </actuator>
  </transmission>
  <!-- nothing to do here at the moment -->
  <!-- ROS base_link to UR 'Base' Coordinates transform -->
  <link name="base"/>
  <joint name="base_link-base_fixed_joint" type="fixed">
    <!-- NOTE: this rotation is only needed as long as base_link itself is
                 not corrected wrt the real robot (ie: rotated over 180
                 degrees)
      -->
    <origin rpy="0 0 -3.14159265359" xyz="0 0 0"/>
    <parent link="base_link"/>
    <child link="base"/>
  </joint>
  <!-- Frame coincident with all-zeros TCP on UR controller -->
  <link name="tool0"/>
  <joint name="wrist_3_link-tool0_fixed_joint" type="fixed">
    <origin rpy="-1.57079632679 0 0" xyz="0 0.0922 0"/>
    <parent link="wrist_3_link"/>
    <child link="tool0"/>
  </joint>
  <!-- Mount link -->
  <link name="mount_link">
    <visual name="visual">
      <geometry>
        <box size="0.3 0.05 0.01"/>
      </geometry>
    </visual>
    <collision name="collision">
      <geometry>
        <box size="0.3 0.05 0.01"/>
      </geometry>
    </collision>
    <inertial>
      <mass value="0.15"/>
      <inertia ixx="3.25e-05" ixy="0.0" ixz="0.0" iyy="0.00112625" iyz="0.0" izz="0.00115625"/>
    </inertial>
  </link>
  <link name="cone_link">
    <visual>
      <origin rpy="0 0 0" xyz="0 0 0"/>
      <geometry>
        <mesh filename="package://mobile_manipulator/models/fixed_cone/meshes/Cone100.STL"/>
      </geometry>
    </visual>
    <collision>
      <origin rpy="0 0 0" xyz="0 0 0"/>
      <geometry>
        <mesh filename="package://mobile_manipulator/models/fixed_cone/meshes/Cone100.STL"/>
      </geometry>
    </collision>
    <inertial>
      <mass value="1"/>
      <inertia ixx="0.01" ixy="0.005" ixz="0.0003" iyy="0.02" iyz="0.00004" izz="0.02"/>
    </inertial>
  </link>
  <gazebo reference="camera_depth_frame">
    <sensor name="camera1" type="depth">
      <always_on>true</always_on>
      <update_rate>20.0</update_rate>
      <camera>
        <horizontal_fov>1.0471975512</horizontal_fov>
        <image>
          <format>R8G8B8</format>
          <width>640</width>
          <height>480</height>
        </image>
        <clip>
          <near>0.05</near>
          <far>8.0</far>
        </clip>
      </camera>
      <plugin filename="libgazebo_ros_openni_kinect.so" name="camera_depth_frame_kinect_controller">
        <baseline>0.1</baseline>
        <alwaysOn>true</alwaysOn>
        <updateRate>10</updateRate>
        <cameraName>camera1</cameraName>
        <imageTopicName>depth/image_raw</imageTopicName>
        <cameraInfoTopicName>depth/camera_info</cameraInfoTopicName>
        <depthImageTopicName>depth/image_raw_depth</depthImageTopicName>
        <depthImageCameraInfoTopicName>depth/camera_info</depthImageCameraInfoTopicName>
        <pointCloudTopicName>depth/points</pointCloudTopicName>
        <frameName>camera_depth_optical_frame</frameName>
        <pointCloudCutoff>0.3</pointCloudCutoff>
        <distortion_k1>0.0</distortion_k1>
        <distortion_k2>0.0</distortion_k2>
        <distortion_k3>0.0</distortion_k3>
        <distortion_t1>0.0</distortion_t1>
        <distortion_t2>0.0</distortion_t2>
        <!--
          <CxPrime>0</CxPrime>
          <Cx>0</Cx>
          <Cy>0</Cy>
          <focalLength>0</focalLength>
          <hackBaseline>0</hackBaseline>
      -->
      </plugin>
    </sensor>
  </gazebo>
  <!-- joints for attaching models to each other -->
  <!-- joint to attach UR10 to mobile base -->
  <joint name="arm_to_mobile_base" type="fixed">
    <origin rpy="0 0 0" xyz="0 0 0.176"/>
    <parent link="chassis"/>
    <child link="base_link"/>
  </joint>
  <!-- joint to attach mount for tool to UR10 -->
  <joint name="mount_to_ur10" type="fixed">
    <origin rpy="0 0 0" xyz="0 0 .005"/>
    <parent link="tool0"/>
    <child link="mount_link"/>
  </joint>
  <joint name="gripper_to_mount" type="fixed">
    <origin rpy="4.71238898038 0 0" xyz="0.2 0 0.252"/>
    <parent link="mount_link"/>
    <child link="cone_link"/>
  </joint>
  <joint name="camera_rgb_joint" type="fixed">
    <origin rpy="0 -1.5708 0" xyz="-0.12 0 0.08"/>
    <parent link="mount_link"/>
    <child link="camera_rgb_frame"/>
  </joint>
  <link name="camera_rgb_frame">
    <inertial>
      <mass value="0.001"/>
      <origin xyz="0 0 0"/>
      <inertia ixx="0.0001" ixy="0.0" ixz="0.0" iyy="0.0001" iyz="0.0" izz="0.0001"/>
    </inertial>
  </link>
  <joint name="camera_rgb_optical_joint" type="fixed">
    <origin rpy="-1.57079632679 0 -1.57079632679" xyz="0 0 0"/>
    <parent link="camera_rgb_frame"/>
    <child link="camera_rgb_optical_frame"/>
  </joint>
  <link name="camera_rgb_optical_frame">
    <inertial>
      <mass value="0.001"/>
      <origin xyz="0 0 0"/>
      <inertia ixx="0.0001" ixy="0.0" ixz="0.0" iyy="0.0001" iyz="0.0" izz="0.0001"/>
    </inertial>
  </link>
  <joint name="camera_joint" type="fixed">
    <origin rpy="0 0 0" xyz="-0.031 0 -0.016"/>
    <parent link="camera_rgb_frame"/>
    <child link="camera_link"/>
  </joint>
  <link name="camera_link">
    <visual>
      <origin rpy="0 0 1.57079632679" xyz="0 0 0"/>
      <geometry>
        <mesh filename="package://mobile_manipulator/models/depth_camera_kinect/meshes/kinect.dae"/>
      </geometry>
    </visual>
    <collision>
      <origin rpy="0 0 0" xyz="0.0 0.0 0.0"/>
      <geometry>
        <box size="0.07271 0.27794 0.073"/>
      </geometry>
    </collision>
    <inertial>
      <mass value="0.001"/>
      <origin xyz="0 0 0"/>
      <inertia ixx="0.0001" ixy="0.0" ixz="0.0" iyy="0.0001" iyz="0.0" izz="0.0001"/>
    </inertial>
  </link>
  <!-- The fixed joints & links below are usually published by static_transformers launched by the OpenNi launch 
		 files. However, for Gazebo simulation we need them, so we add them here.
		 (Hence, don't publish them additionally!) -->
  <joint name="camera_depth_joint" type="fixed">
    <origin rpy="0 0 0" xyz="0 0 0"/>
    <parent link="camera_rgb_frame"/>
    <child link="camera_depth_frame"/>
  </joint>
  <link name="camera_depth_frame">
    <inertial>
      <mass value="0.001"/>
      <origin xyz="0 0 0"/>
      <inertia ixx="0.0001" ixy="0.0" ixz="0.0" iyy="0.0001" iyz="0.0" izz="0.0001"/>
    </inertial>
  </link>
  <joint name="camera_depth_optical_joint" type="fixed">
    <origin rpy="-1.57079632679 0 -1.57079632679" xyz="0 0 0"/>
    <parent link="camera_depth_frame"/>
    <child link="camera_depth_optical_frame"/>
  </joint>
  <link name="camera_depth_optical_frame">
    <inertial>
      <mass value="0.001"/>
      <origin xyz="0 0 0"/>
      <inertia ixx="0.0001" ixy="0.0" ixz="0.0" iyy="0.0001" iyz="0.0" izz="0.0001"/>
    </inertial>
  </link>
  <gazebo>
    <plugin filename="libgazebo_ros_control.so" name="ros_control"/>
  </gazebo>
</robot>

