<?xml version="1.0" ?>
<!-- =================================================================================== -->
<!-- |    This document was autogenerated by xacro from mobile_base.urdf.xacro         | -->
<!-- |    EDITING THIS FILE BY HAND IS NOT RECOMMENDED                                 | -->
<!-- =================================================================================== -->
<robot name="fake_MiR200" xmlns:xacro="http://ros.org/wiki/xacro">
  <!-- Chassis link -->
  <link name="chassis">
    <visual name="visual">
      <geometry>
        <box size="0.89 0.58 0.2"/>
      </geometry>
    </visual>
    <collision name="collision">
      <geometry>
        <box size="0.89 0.58 0.2"/>
      </geometry>
    </collision>
    <inertial>
      <mass value="63.65"/>
      <inertia ixx="1.99648833333" ixy="0.0" ixz="0.0" iyy="4.41359708333" iyz="0.0" izz="5.98575208333"/>
    </inertial>
  </link>
  <link name="wheel_1_link">
    <!-- Note: must omit name="foo" because in Gazebo 7 the urdf parser has a bug that would make <gazebo reference="bar"> not work -->
    <visual>
      <geometry>
        <cylinder length="0.02" radius="0.071"/>
      </geometry>
      <material name="red">
        <color rgba="1 0 0 1"/>
      </material>
    </visual>
    <!-- Note: must omit name="foo" because in Gazebo 7 the urdf parser has a bug that would make <gazebo reference="bar"> not work -->
    <collision>
      <geometry>
        <cylinder length="0.02" radius="0.071"/>
      </geometry>
    </collision>
    <inertial>
      <mass value="0.558333333333"/>
      <inertia ixx="0.000722250694444" ixy="0.0" ixz="0.0" iyy="0.000722250694444" iyz="0.0" izz="0.00140727916667"/>
    </inertial>
  </link>
  <joint name="wheel_1_joint" type="fixed">
    <axis xyz="0 0 1"/>
    <parent link="chassis"/>
    <child link="wheel_1_link"/>
    <origin rpy="-1.57079632679 0 0" xyz="0.374 0.28 -0.181"/>
  </joint>
  <link name="wheel_2_link">
    <!-- Note: must omit name="foo" because in Gazebo 7 the urdf parser has a bug that would make <gazebo reference="bar"> not work -->
    <visual>
      <geometry>
        <cylinder length="0.02" radius="0.071"/>
      </geometry>
      <material name="red">
        <color rgba="1 0 0 1"/>
      </material>
    </visual>
    <!-- Note: must omit name="foo" because in Gazebo 7 the urdf parser has a bug that would make <gazebo reference="bar"> not work -->
    <collision>
      <geometry>
        <cylinder length="0.02" radius="0.071"/>
      </geometry>
    </collision>
    <inertial>
      <mass value="0.558333333333"/>
      <inertia ixx="0.000722250694444" ixy="0.0" ixz="0.0" iyy="0.000722250694444" iyz="0.0" izz="0.00140727916667"/>
    </inertial>
  </link>
  <joint name="wheel_2_joint" type="fixed">
    <axis xyz="0 0 1"/>
    <parent link="chassis"/>
    <child link="wheel_2_link"/>
    <origin rpy="-1.57079632679 0 0" xyz="0 0.28 -0.181"/>
  </joint>
  <link name="wheel_3_link">
    <!-- Note: must omit name="foo" because in Gazebo 7 the urdf parser has a bug that would make <gazebo reference="bar"> not work -->
    <visual>
      <geometry>
        <cylinder length="0.02" radius="0.071"/>
      </geometry>
      <material name="red">
        <color rgba="1 0 0 1"/>
      </material>
    </visual>
    <!-- Note: must omit name="foo" because in Gazebo 7 the urdf parser has a bug that would make <gazebo reference="bar"> not work -->
    <collision>
      <geometry>
        <cylinder length="0.02" radius="0.071"/>
      </geometry>
    </collision>
    <inertial>
      <mass value="0.558333333333"/>
      <inertia ixx="0.000722250694444" ixy="0.0" ixz="0.0" iyy="0.000722250694444" iyz="0.0" izz="0.00140727916667"/>
    </inertial>
  </link>
  <joint name="wheel_3_joint" type="fixed">
    <axis xyz="0 0 1"/>
    <parent link="chassis"/>
    <child link="wheel_3_link"/>
    <origin rpy="-1.57079632679 0 0" xyz="-0.374 0.28 -0.181"/>
  </joint>
  <link name="wheel_4_link">
    <!-- Note: must omit name="foo" because in Gazebo 7 the urdf parser has a bug that would make <gazebo reference="bar"> not work -->
    <visual>
      <geometry>
        <cylinder length="0.02" radius="0.071"/>
      </geometry>
      <material name="red">
        <color rgba="1 0 0 1"/>
      </material>
    </visual>
    <!-- Note: must omit name="foo" because in Gazebo 7 the urdf parser has a bug that would make <gazebo reference="bar"> not work -->
    <collision>
      <geometry>
        <cylinder length="0.02" radius="0.071"/>
      </geometry>
    </collision>
    <inertial>
      <mass value="0.558333333333"/>
      <inertia ixx="0.000722250694444" ixy="0.0" ixz="0.0" iyy="0.000722250694444" iyz="0.0" izz="0.00140727916667"/>
    </inertial>
  </link>
  <joint name="wheel_4_joint" type="fixed">
    <axis xyz="0 0 1"/>
    <parent link="chassis"/>
    <child link="wheel_4_link"/>
    <origin rpy="-1.57079632679 0 0" xyz="-0.374 -0.28 -0.181"/>
  </joint>
  <link name="wheel_5_link">
    <!-- Note: must omit name="foo" because in Gazebo 7 the urdf parser has a bug that would make <gazebo reference="bar"> not work -->
    <visual>
      <geometry>
        <cylinder length="0.02" radius="0.071"/>
      </geometry>
      <material name="red">
        <color rgba="1 0 0 1"/>
      </material>
    </visual>
    <!-- Note: must omit name="foo" because in Gazebo 7 the urdf parser has a bug that would make <gazebo reference="bar"> not work -->
    <collision>
      <geometry>
        <cylinder length="0.02" radius="0.071"/>
      </geometry>
    </collision>
    <inertial>
      <mass value="0.558333333333"/>
      <inertia ixx="0.000722250694444" ixy="0.0" ixz="0.0" iyy="0.000722250694444" iyz="0.0" izz="0.00140727916667"/>
    </inertial>
  </link>
  <joint name="wheel_5_joint" type="fixed">
    <axis xyz="0 0 1"/>
    <parent link="chassis"/>
    <child link="wheel_5_link"/>
    <origin rpy="-1.57079632679 0 0" xyz="0 -0.28 -0.181"/>
  </joint>
  <link name="wheel_6_link">
    <!-- Note: must omit name="foo" because in Gazebo 7 the urdf parser has a bug that would make <gazebo reference="bar"> not work -->
    <visual>
      <geometry>
        <cylinder length="0.02" radius="0.071"/>
      </geometry>
      <material name="red">
        <color rgba="1 0 0 1"/>
      </material>
    </visual>
    <!-- Note: must omit name="foo" because in Gazebo 7 the urdf parser has a bug that would make <gazebo reference="bar"> not work -->
    <collision>
      <geometry>
        <cylinder length="0.02" radius="0.071"/>
      </geometry>
    </collision>
    <inertial>
      <mass value="0.558333333333"/>
      <inertia ixx="0.000722250694444" ixy="0.0" ixz="0.0" iyy="0.000722250694444" iyz="0.0" izz="0.00140727916667"/>
    </inertial>
  </link>
  <joint name="wheel_6_joint" type="fixed">
    <axis xyz="0 0 1"/>
    <parent link="chassis"/>
    <child link="wheel_6_link"/>
    <origin rpy="-1.57079632679 0 0" xyz="0.374 -0.28 -0.181"/>
  </joint>
  <link name="world"/>
  <joint name="prismatic_chassis_to_world" type="prismatic">
    <origin rpy="0 0 0" xyz="0 0 0.252"/>
    <parent link="world"/>
    <child link="chassis"/>
    <axis xyz="1 0 0"/>
    <limit effort="1000.0" lower="-100" upper="100" velocity="2"/>
  </joint>
  <transmission name="prismatic_chassis_to_world_trans">
    <type>transmission_interface/SimpleTransmission</type>
    <joint name="prismatic_chassis_to_world">
      <hardwareInterface>hardware_interface/EffortJointInterface</hardwareInterface>
    </joint>
    <actuator name="prismatic_chassis_to_world_motor">
      <hardwareInterface>hardware_interface/EffortJointInterface</hardwareInterface>
      <mechanicalReduction>1</mechanicalReduction>
    </actuator>
  </transmission>
</robot>
